{"content": {"suites": {"0": {"status": {"total_pass": 0, "total_skip": 0, "total_xpass": 0, "total_xfail": 0, "total_rerun": 0, "total_fail": 0, "total_error": 8}, "tests": {"0": {"status": "ERROR", "message": "setup_saved_user = [{'active': True, 'email': 'testuser1@kpmg.com', 'first_name': 'test', 'hashkey': '3eca83df-8', ...}, {'active': True,...db-9', ...}, {'active': False, 'email': 'testuser6@kpmg.com', 'first_name': 'test', 'hashkey': 'aadd8181-e', ...}, ...]\n\n    @pytest.fixture\n    def setup_multiple_invalid(setup_saved_user):\n    \n    \tusers=Users.objects.exclude(id=1)\n    \tfor user in users:\n    \t\tgetAccess=AccessManagement.objects.get(name=user)\n>   \t\tgetAccess.last_login_attempt=(datetime.datetime.now(tz=timezone.utc)\n                                    +timedelta(minutes=refresh_lockout+5))\nE     AttributeError: type object 'datetime.datetime' has no attribute 'datetime'\n\n..\\..\\conftest.py:281: AttributeError\n", "test_name": "test_login_with_multiple_invalid_attempt[testuser1@kpmg.com-Password@123]", "rerun": "0"}, "1": {"status": "ERROR", "message": "setup_saved_user = [{'active': True, 'email': 'testuser1@kpmg.com', 'first_name': 'test', 'hashkey': '6d2910e5-3', ...}, {'active': True,...5e-d', ...}, {'active': False, 'email': 'testuser6@kpmg.com', 'first_name': 'test', 'hashkey': '8d441680-8', ...}, ...]\n\n    @pytest.fixture\n    def setup_multiple_invalid(setup_saved_user):\n    \n    \tusers=Users.objects.exclude(id=1)\n    \tfor user in users:\n    \t\tgetAccess=AccessManagement.objects.get(name=user)\n>   \t\tgetAccess.last_login_attempt=(datetime.datetime.now(tz=timezone.utc)\n                                    +timedelta(minutes=refresh_lockout+5))\nE     AttributeError: type object 'datetime.datetime' has no attribute 'datetime'\n\n..\\..\\conftest.py:281: AttributeError\n", "test_name": "test_login_with_multiple_invalid_attempt[testuser2@kpmg.com-Password@123]", "rerun": "0"}, "2": {"status": "ERROR", "message": "setup_saved_user = [{'active': True, 'email': 'testuser1@kpmg.com', 'first_name': 'test', 'hashkey': 'e2aae63e-e', ...}, {'active': True,...e8-7', ...}, {'active': False, 'email': 'testuser6@kpmg.com', 'first_name': 'test', 'hashkey': '0f02f6b0-4', ...}, ...]\n\n    @pytest.fixture\n    def setup_multiple_invalid(setup_saved_user):\n    \n    \tusers=Users.objects.exclude(id=1)\n    \tfor user in users:\n    \t\tgetAccess=AccessManagement.objects.get(name=user)\n>   \t\tgetAccess.last_login_attempt=(datetime.datetime.now(tz=timezone.utc)\n                                    +timedelta(minutes=refresh_lockout+5))\nE     AttributeError: type object 'datetime.datetime' has no attribute 'datetime'\n\n..\\..\\conftest.py:281: AttributeError\n", "test_name": "test_login_with_multiple_invalid_attempt[testuser3@kpmg.com-Password@123]", "rerun": "0"}, "3": {"status": "ERROR", "message": "setup_saved_user = [{'active': True, 'email': 'testuser1@kpmg.com', 'first_name': 'test', 'hashkey': '97410e19-e', ...}, {'active': True,...49-8', ...}, {'active': False, 'email': 'testuser6@kpmg.com', 'first_name': 'test', 'hashkey': 'c22e4a40-a', ...}, ...]\n\n    @pytest.fixture\n    def setup_multiple_invalid(setup_saved_user):\n    \n    \tusers=Users.objects.exclude(id=1)\n    \tfor user in users:\n    \t\tgetAccess=AccessManagement.objects.get(name=user)\n>   \t\tgetAccess.last_login_attempt=(datetime.datetime.now(tz=timezone.utc)\n                                    +timedelta(minutes=refresh_lockout+5))\nE     AttributeError: type object 'datetime.datetime' has no attribute 'datetime'\n\n..\\..\\conftest.py:281: AttributeError\n", "test_name": "test_login_with_multiple_invalid_attempt[testuser4@kpmg.com-Password@123]", "rerun": "0"}, "4": {"status": "ERROR", "message": "setup_saved_user = [{'active': True, 'email': 'testuser1@kpmg.com', 'first_name': 'test', 'hashkey': '5020cfa6-f', ...}, {'active': True,...b0-e', ...}, {'active': False, 'email': 'testuser6@kpmg.com', 'first_name': 'test', 'hashkey': '3d614bd1-5', ...}, ...]\n\n    @pytest.fixture\n    def setup_multiple_invalid(setup_saved_user):\n    \n    \tusers=Users.objects.exclude(id=1)\n    \tfor user in users:\n    \t\tgetAccess=AccessManagement.objects.get(name=user)\n>   \t\tgetAccess.last_login_attempt=(datetime.datetime.now(tz=timezone.utc)\n                                    +timedelta(minutes=refresh_lockout+5))\nE     AttributeError: type object 'datetime.datetime' has no attribute 'datetime'\n\n..\\..\\conftest.py:281: AttributeError\n", "test_name": "test_login_with_multiple_invalid_attempt[testuser5@kpmg.com-Password@123]", "rerun": "0"}, "5": {"status": "ERROR", "message": "setup_saved_user = [{'active': True, 'email': 'testuser1@kpmg.com', 'first_name': 'test', 'hashkey': '8180e58c-9', ...}, {'active': True,...c1-c', ...}, {'active': False, 'email': 'testuser6@kpmg.com', 'first_name': 'test', 'hashkey': 'cd0f91a3-3', ...}, ...]\n\n    @pytest.fixture\n    def setup_multiple_invalid(setup_saved_user):\n    \n    \tusers=Users.objects.exclude(id=1)\n    \tfor user in users:\n    \t\tgetAccess=AccessManagement.objects.get(name=user)\n>   \t\tgetAccess.last_login_attempt=(datetime.datetime.now(tz=timezone.utc)\n                                    +timedelta(minutes=refresh_lockout+5))\nE     AttributeError: type object 'datetime.datetime' has no attribute 'datetime'\n\n..\\..\\conftest.py:281: AttributeError\n", "test_name": "test_login_with_multiple_invalid_attempt[testuser6@kpmg.com-Password@123]", "rerun": "0"}, "6": {"status": "ERROR", "message": "setup_saved_user = [{'active': True, 'email': 'testuser1@kpmg.com', 'first_name': 'test', 'hashkey': '361f6b93-4', ...}, {'active': True,...b2-3', ...}, {'active': False, 'email': 'testuser6@kpmg.com', 'first_name': 'test', 'hashkey': 'c1a5f40d-c', ...}, ...]\n\n    @pytest.fixture\n    def setup_multiple_invalid(setup_saved_user):\n    \n    \tusers=Users.objects.exclude(id=1)\n    \tfor user in users:\n    \t\tgetAccess=AccessManagement.objects.get(name=user)\n>   \t\tgetAccess.last_login_attempt=(datetime.datetime.now(tz=timezone.utc)\n                                    +timedelta(minutes=refresh_lockout+5))\nE     AttributeError: type object 'datetime.datetime' has no attribute 'datetime'\n\n..\\..\\conftest.py:281: AttributeError\n", "test_name": "test_login_with_multiple_invalid_attempt[testuser7@kpmg.com-Password@123]", "rerun": "0"}, "7": {"status": "ERROR", "message": "setup_saved_user = [{'active': True, 'email': 'testuser1@kpmg.com', 'first_name': 'test', 'hashkey': '4b2926e2-5', ...}, {'active': True,...e9-e', ...}, {'active': False, 'email': 'testuser6@kpmg.com', 'first_name': 'test', 'hashkey': 'a8a57d89-2', ...}, ...]\n\n    @pytest.fixture\n    def setup_multiple_invalid(setup_saved_user):\n    \n    \tusers=Users.objects.exclude(id=1)\n    \tfor user in users:\n    \t\tgetAccess=AccessManagement.objects.get(name=user)\n>   \t\tgetAccess.last_login_attempt=(datetime.datetime.now(tz=timezone.utc)\n                                    +timedelta(minutes=refresh_lockout+5))\nE     AttributeError: type object 'datetime.datetime' has no attribute 'datetime'\n\n..\\..\\conftest.py:281: AttributeError\n", "test_name": "test_login_with_multiple_invalid_attempt[testuser8@kpmg.com-Password@123]", "rerun": "0"}}, "suite_name": "usermanagement/Test_usermanagement/test_views.py"}}}, "date": "August 18, 2021", "start_time": 1629291503.186275, "total_suite": 1, "status": "FAIL", "status_list": {"pass": "0", "fail": "0", "skip": "0", "error": "8", "xpass": "0", "xfail": "0", "rerun": "0"}, "total_tests": "8"}